		g3log created log at: Thu Mar 02 11:02:58 2023
		LOG format: [YYYY/MM/DD hh:mm:ss uuu* LEVEL FILE->FUNCTION:LINE] messagen
		(uuu*: microseconds fractions of the seconds value)

2023/03/02 11:02:58 983691	INFO [python_manager.cpp->PythonManager::InitializePython:127]	Initializing Python ... 
2023/03/02 11:02:58 999881	INFO [python_manager.cpp->PythonManager::InitializePython:129]	Initializing Python DONE... 
2023/03/02 11:02:58 999888	INFO [python_manager.cpp->PythonManager::InitNumpy:172]	Init numpy... 
2023/03/02 11:02:59 106480	INFO [python_manager.cpp->PythonManager::InitNumpy:174]	Init numpy DONE... 
2023/03/02 11:08:11 475393	INFO [python_manager.cpp->PythonManager::Death:637]	Death()
2023/03/02 11:14:19 064419	WARNING [python_manager.cpp->PythonManager::CheckForErrors:745]	Error, traceback : ['Traceback (most recent call last):
', '  File "C:/Users/user/OneDrive - ESTACA/Desktop/ESTAPARK2023/RTMapsYOLOv7\\BlocTracking (1).py", line 408, in Core
    ImageOut.data.image_data = drawImage(ImageOut.data.image_data,self.classIds,self.trackingIds,self.trackingBoxes)
', '  File "C:/Users/user/OneDrive - ESTACA/Desktop/ESTAPARK2023/RTMapsYOLOv7\\BlocTracking (1).py", line 164, in drawImage
    Frame = cv2.rectangle(Frame,(x1,y1),(x2,y2),(244,80,60),2)
', "cv2.error: OpenCV(4.5.4-dev) :-1: error: (-5:Bad argument) in function 'rectangle'
> Overload resolution failed:
>  - Can't parse 'pt1'. Sequence item with index 1 has a wrong type
>  - Can't parse 'pt1'. Sequence item with index 1 has a wrong type
>  - Can't parse 'rec'. Expected sequence length 4, got 2
>  - Can't parse 'rec'. Expected sequence length 4, got 2

"]
2023/03/02 11:14:19 065080	INFO [python_manager.cpp->PythonManager::Death:637]	Death()
2023/03/02 11:14:30 772699	WARNING [python_manager.cpp->PythonManager::CheckForErrors:745]	Error, traceback : ['Traceback (most recent call last):
', '  File "C:/Users/user/OneDrive - ESTACA/Desktop/ESTAPARK2023/RTMapsYOLOv7\\BlocTracking (1).py", line 408, in Core
    ImageOut.data.image_data = drawImage(ImageOut.data.image_data,self.classIds,self.trackingIds,self.trackingBoxes)
', '  File "C:/Users/user/OneDrive - ESTACA/Desktop/ESTAPARK2023/RTMapsYOLOv7\\BlocTracking (1).py", line 164, in drawImage
    Frame = cv2.rectangle(Frame,(x1,y1),(x2,y2),(244,80,60),2)
', "cv2.error: OpenCV(4.5.4-dev) :-1: error: (-5:Bad argument) in function 'rectangle'
> Overload resolution failed:
>  - Can't parse 'pt1'. Sequence item with index 1 has a wrong type
>  - Can't parse 'pt1'. Sequence item with index 1 has a wrong type
>  - Can't parse 'rec'. Expected sequence length 4, got 2
>  - Can't parse 'rec'. Expected sequence length 4, got 2

"]
2023/03/02 11:14:30 783654	INFO [python_manager.cpp->PythonManager::Death:637]	Death()
2023/03/02 11:14:54 140202	INFO [python_manager.cpp->PythonManager::Death:637]	Death()
2023/03/02 11:15:06 948974	INFO [python_manager.cpp->PythonManager::Death:637]	Death()
2023/03/02 11:15:21 510668	INFO [python_manager.cpp->PythonManager::Death:637]	Death()
2023/03/02 11:15:53 859896	WARNING [python_manager.cpp->PythonManager::CheckForErrors:745]	Error, traceback : ['Traceback (most recent call last):
', '  File "C:/Users/user/OneDrive - ESTACA/Desktop/ESTAPARK2023/RTMapsYOLOv7\\BlocTracking (1).py", line 408, in Core
    ImageOut.data.image_data = drawImage(ImageOut.data.image_data,self.classIds,self.trackingIds,self.trackingBoxes)
', '  File "C:/Users/user/OneDrive - ESTACA/Desktop/ESTAPARK2023/RTMapsYOLOv7\\BlocTracking (1).py", line 164, in drawImage
    Frame = cv2.rectangle(Frame,(x1,y1),(x2,y2),(244,80,60),2)
', "cv2.error: OpenCV(4.5.4-dev) :-1: error: (-5:Bad argument) in function 'rectangle'
> Overload resolution failed:
>  - Can't parse 'pt1'. Sequence item with index 1 has a wrong type
>  - Can't parse 'pt1'. Sequence item with index 1 has a wrong type
>  - Can't parse 'rec'. Expected sequence length 4, got 2
>  - Can't parse 'rec'. Expected sequence length 4, got 2

"]
2023/03/02 11:15:53 860549	INFO [python_manager.cpp->PythonManager::Death:637]	Death()
2023/03/02 11:16:07 639190	WARNING [python_manager.cpp->PythonManager::CheckForErrors:745]	Error, traceback : ['Traceback (most recent call last):
', '  File "C:/Users/user/OneDrive - ESTACA/Desktop/ESTAPARK2023/RTMapsYOLOv7\\BlocTracking (1).py", line 408, in Core
    ImageOut.data.image_data = drawImage(ImageOut.data.image_data,self.classIds,self.trackingIds,self.trackingBoxes)
', '  File "C:/Users/user/OneDrive - ESTACA/Desktop/ESTAPARK2023/RTMapsYOLOv7\\BlocTracking (1).py", line 164, in drawImage
    Frame = cv2.rectangle(Frame,(x1,y1),(x2,y2),(244,80,60),2)
', "cv2.error: OpenCV(4.5.4-dev) :-1: error: (-5:Bad argument) in function 'rectangle'
> Overload resolution failed:
>  - Can't parse 'pt1'. Sequence item with index 1 has a wrong type
>  - Can't parse 'pt1'. Sequence item with index 1 has a wrong type
>  - Can't parse 'rec'. Expected sequence length 4, got 2
>  - Can't parse 'rec'. Expected sequence length 4, got 2

"]
2023/03/02 11:16:07 679111	INFO [python_manager.cpp->PythonManager::Death:637]	Death()
2023/03/02 11:21:20 574220	WARNING [python_manager.cpp->PythonManager::CheckForErrors:745]	Error, traceback : ['Traceback (most recent call last):
', '  File "C:/Users/user/OneDrive - ESTACA/Desktop/ESTAPARK2023/RTMapsYOLOv7\\BlocTracking (1).py", line 408, in Core
    ImageOut.data.image_data = drawImage(ImageOut.data.image_data,self.classIds,self.trackingIds,self.trackingBoxes)
', '  File "C:/Users/user/OneDrive - ESTACA/Desktop/ESTAPARK2023/RTMapsYOLOv7\\BlocTracking (1).py", line 164, in drawImage
    Frame = cv2.rectangle(Frame,(x1,y1),(x2,y2),(244,80,60),2)
', "cv2.error: OpenCV(4.5.4-dev) :-1: error: (-5:Bad argument) in function 'rectangle'
> Overload resolution failed:
>  - Can't parse 'pt1'. Sequence item with index 1 has a wrong type
>  - Can't parse 'pt1'. Sequence item with index 1 has a wrong type
>  - Can't parse 'rec'. Expected sequence length 4, got 2
>  - Can't parse 'rec'. Expected sequence length 4, got 2

"]
2023/03/02 11:21:20 605475	INFO [python_manager.cpp->PythonManager::Death:637]	Death()
2023/03/02 11:23:35 675553	WARNING [python_manager.cpp->PythonManager::CheckForErrors:745]	Error, traceback : ['Traceback (most recent call last):
', '  File "C:/Users/user/OneDrive - ESTACA/Desktop/ESTAPARK2023/RTMapsYOLOv7\\BlocTracking (1).py", line 408, in Core
    ImageOut.data.image_data = drawImage(ImageOut.data.image_data,self.classIds,self.trackingIds,self.trackingBoxes)
', '  File "C:/Users/user/OneDrive - ESTACA/Desktop/ESTAPARK2023/RTMapsYOLOv7\\BlocTracking (1).py", line 164, in drawImage
    Frame = cv2.rectangle(Frame,(x1,y1),(x2,y2),(244,80,60),2)
', "cv2.error: OpenCV(4.5.4-dev) :-1: error: (-5:Bad argument) in function 'rectangle'
> Overload resolution failed:
>  - Can't parse 'pt1'. Sequence item with index 1 has a wrong type
>  - Can't parse 'pt1'. Sequence item with index 1 has a wrong type
>  - Can't parse 'rec'. Expected sequence length 4, got 2
>  - Can't parse 'rec'. Expected sequence length 4, got 2

"]
2023/03/02 11:23:35 752978	INFO [python_manager.cpp->PythonManager::Death:637]	Death()
2023/03/02 11:23:53 071919	INFO [python_manager.cpp->PythonManager::Death:637]	Death()
2023/03/02 11:24:08 630255	INFO [python_manager.cpp->PythonManager::Death:637]	Death()
2023/03/02 11:25:35 154411	WARNING [python_manager.cpp->PythonManager::CheckForErrors:745]	Error, traceback : ['Traceback (most recent call last):
', '  File "C:/Users/user/OneDrive - ESTACA/Desktop/ESTAPARK2023/RTMapsYOLOv7\\BlocTracking (1).py", line 408, in Core
    ImageOut.data.image_data = drawImage(ImageOut.data.image_data,self.classIds,self.trackingIds,self.trackingBoxes)
', '  File "C:/Users/user/OneDrive - ESTACA/Desktop/ESTAPARK2023/RTMapsYOLOv7\\BlocTracking (1).py", line 164, in drawImage
    Frame = cv2.rectangle(Frame,(x1,y1),(x2,y2),(244,80,60),2)
', "cv2.error: OpenCV(4.5.4-dev) :-1: error: (-5:Bad argument) in function 'rectangle'
> Overload resolution failed:
>  - Can't parse 'pt1'. Sequence item with index 1 has a wrong type
>  - Can't parse 'pt1'. Sequence item with index 1 has a wrong type
>  - Can't parse 'rec'. Expected sequence length 4, got 2
>  - Can't parse 'rec'. Expected sequence length 4, got 2

"]
2023/03/02 11:25:35 154712	INFO [python_manager.cpp->PythonManager::Death:637]	Death()
2023/03/02 11:26:20 337301	INFO [python_manager.cpp->PythonManager::Death:637]	Death()
2023/03/02 11:27:13 565595	WARNING [python_manager.cpp->PythonManager::CheckForErrors:745]	Error, traceback : ['Traceback (most recent call last):
', '  File "C:/Users/user/OneDrive - ESTACA/Desktop/ESTAPARK2023/RTMapsYOLOv7\\BlocTracking (1).py", line 408, in Core
    ImageOut.data.image_data = drawImage(ImageOut.data.image_data,self.classIds,self.trackingIds,self.trackingBoxes)
', '  File "C:/Users/user/OneDrive - ESTACA/Desktop/ESTAPARK2023/RTMapsYOLOv7\\BlocTracking (1).py", line 164, in drawImage
    Frame = cv2.rectangle(Frame,(x1,y1),(x2,y2),(244,80,60),2)
', "cv2.error: OpenCV(4.5.4-dev) :-1: error: (-5:Bad argument) in function 'rectangle'
> Overload resolution failed:
>  - Can't parse 'pt1'. Sequence item with index 1 has a wrong type
>  - Can't parse 'pt1'. Sequence item with index 1 has a wrong type
>  - Can't parse 'rec'. Expected sequence length 4, got 2
>  - Can't parse 'rec'. Expected sequence length 4, got 2

"]
2023/03/02 11:27:13 566612	INFO [python_manager.cpp->PythonManager::Death:637]	Death()
2023/03/02 11:28:02 215206	WARNING [python_manager.cpp->PythonManager::CheckForErrors:745]	Error, traceback : ['Traceback (most recent call last):
', '  File "C:/Users/user/OneDrive - ESTACA/Desktop/ESTAPARK2023/RTMapsYOLOv7\\BlocTracking (1).py", line 408, in Core
    ImageOut.data.image_data = drawImage(ImageOut.data.image_data,self.classIds,self.trackingIds,self.trackingBoxes)
', '  File "C:/Users/user/OneDrive - ESTACA/Desktop/ESTAPARK2023/RTMapsYOLOv7\\BlocTracking (1).py", line 164, in drawImage
    Frame = cv2.rectangle(Frame,(x1,y1),(x2,y2),(244,80,60),2)
', "cv2.error: OpenCV(4.5.4-dev) :-1: error: (-5:Bad argument) in function 'rectangle'
> Overload resolution failed:
>  - Can't parse 'pt1'. Sequence item with index 1 has a wrong type
>  - Can't parse 'pt1'. Sequence item with index 1 has a wrong type
>  - Can't parse 'rec'. Expected sequence length 4, got 2
>  - Can't parse 'rec'. Expected sequence length 4, got 2

"]
2023/03/02 11:28:02 215954	INFO [python_manager.cpp->PythonManager::Death:637]	Death()
2023/03/02 11:28:22 331823	WARNING [python_manager.cpp->PythonManager::CheckForErrors:745]	Error, traceback : ['Traceback (most recent call last):
', '  File "C:/Users/user/OneDrive - ESTACA/Desktop/ESTAPARK2023/RTMapsYOLOv7\\BlocTracking (1).py", line 408, in Core
    ImageOut.data.image_data = drawImage(ImageOut.data.image_data,self.classIds,self.trackingIds,self.trackingBoxes)
', '  File "C:/Users/user/OneDrive - ESTACA/Desktop/ESTAPARK2023/RTMapsYOLOv7\\BlocTracking (1).py", line 164, in drawImage
    Frame = cv2.rectangle(Frame,(x1,y1),(x2,y2),(244,80,60),2)
', "cv2.error: OpenCV(4.5.4-dev) :-1: error: (-5:Bad argument) in function 'rectangle'
> Overload resolution failed:
>  - Can't parse 'pt1'. Sequence item with index 1 has a wrong type
>  - Can't parse 'pt1'. Sequence item with index 1 has a wrong type
>  - Can't parse 'rec'. Expected sequence length 4, got 2
>  - Can't parse 'rec'. Expected sequence length 4, got 2

"]
2023/03/02 11:28:22 332133	INFO [python_manager.cpp->PythonManager::Death:637]	Death()
2023/03/02 11:29:04 528462	WARNING [python_manager.cpp->PythonManager::CheckForErrors:745]	Error, traceback : ['Traceback (most recent call last):
', '  File "C:/Users/user/OneDrive - ESTACA/Desktop/ESTAPARK2023/RTMapsYOLOv7\\BlocTracking (1).py", line 408, in Core
    ImageOut.data.image_data = drawImage(ImageOut.data.image_data,self.classIds,self.trackingIds,self.trackingBoxes)
', '  File "C:/Users/user/OneDrive - ESTACA/Desktop/ESTAPARK2023/RTMapsYOLOv7\\BlocTracking (1).py", line 164, in drawImage
    Frame = cv2.rectangle(Frame,(x1,y1),(x2,y2),(244,80,60),2)
', "cv2.error: OpenCV(4.5.4-dev) :-1: error: (-5:Bad argument) in function 'rectangle'
> Overload resolution failed:
>  - Can't parse 'pt1'. Sequence item with index 1 has a wrong type
>  - Can't parse 'pt1'. Sequence item with index 1 has a wrong type
>  - Can't parse 'rec'. Expected sequence length 4, got 2
>  - Can't parse 'rec'. Expected sequence length 4, got 2

"]
2023/03/02 11:29:04 528829	INFO [python_manager.cpp->PythonManager::Death:637]	Death()
2023/03/02 11:30:50 973318	INFO [python_manager.cpp->PythonManager::Death:637]	Death()
2023/03/02 11:31:08 365614	INFO [python_manager.cpp->PythonManager::Death:637]	Death()
2023/03/02 11:32:43 630483	WARNING [python_manager.cpp->PythonManager::CheckForErrors:745]	Error, traceback : ['Traceback (most recent call last):
', '  File "C:/Users/user/OneDrive - ESTACA/Desktop/ESTAPARK2023/RTMapsYOLOv7\\BlocTracking (1).py", line 408, in Core
    ImageOut.data.image_data = drawImage(ImageOut.data.image_data,self.classIds,self.trackingIds,self.trackingBoxes)
', '  File "C:/Users/user/OneDrive - ESTACA/Desktop/ESTAPARK2023/RTMapsYOLOv7\\BlocTracking (1).py", line 164, in drawImage
    Frame = cv2.rectangle(Frame,(x1,y1),(x2,y2),(244,80,60),2)
', "cv2.error: OpenCV(4.5.4-dev) :-1: error: (-5:Bad argument) in function 'rectangle'
> Overload resolution failed:
>  - Can't parse 'pt1'. Sequence item with index 1 has a wrong type
>  - Can't parse 'pt1'. Sequence item with index 1 has a wrong type
>  - Can't parse 'rec'. Expected sequence length 4, got 2
>  - Can't parse 'rec'. Expected sequence length 4, got 2

"]
2023/03/02 11:32:43 643568	INFO [python_manager.cpp->PythonManager::Death:637]	Death()
2023/03/02 11:33:05 466108	INFO [python_manager.cpp->PythonManager::Death:637]	Death()
2023/03/02 11:34:34 993517	INFO [python_manager.cpp->PythonManager::Death:637]	Death()
2023/03/02 11:35:32 988781	INFO [python_manager.cpp->PythonManager::Death:637]	Death()
2023/03/02 11:36:29 673846	INFO [python_manager.cpp->PythonManager::Death:637]	Death()
2023/03/02 11:37:30 126471	WARNING [python_manager.cpp->PythonManager::CheckForErrors:745]	Error, traceback : ['Traceback (most recent call last):
', '  File "C:/Users/user/OneDrive - ESTACA/Desktop/ESTAPARK2023/RTMapsYOLOv7\\BlocTracking (1).py", line 408, in Core
    ImageOut.data.image_data = drawImage(ImageOut.data.image_data,self.classIds,self.trackingIds,self.trackingBoxes)
', '  File "C:/Users/user/OneDrive - ESTACA/Desktop/ESTAPARK2023/RTMapsYOLOv7\\BlocTracking (1).py", line 164, in drawImage
    Frame = cv2.rectangle(Frame,(x1,y1),(x2,y2),(244,80,60),2)
', "cv2.error: OpenCV(4.5.4-dev) :-1: error: (-5:Bad argument) in function 'rectangle'
> Overload resolution failed:
>  - Can't parse 'pt1'. Sequence item with index 1 has a wrong type
>  - Can't parse 'pt1'. Sequence item with index 1 has a wrong type
>  - Can't parse 'rec'. Expected sequence length 4, got 2
>  - Can't parse 'rec'. Expected sequence length 4, got 2

"]
2023/03/02 11:37:30 127391	INFO [python_manager.cpp->PythonManager::Death:637]	Death()
2023/03/02 11:37:38 513798	INFO [python_manager.cpp->PythonManager::Death:637]	Death()
2023/03/02 11:37:41 480865	INFO [python_manager.cpp->PythonManager::ProcessRTMapsAction:210]	Exiting now! All went well.
