		g3log created log at: Wed Apr 26 09:52:11 2023
		LOG format: [YYYY/MM/DD hh:mm:ss uuu* LEVEL FILE->FUNCTION:LINE] messagen
		(uuu*: microseconds fractions of the seconds value)

2023/04/26 09:52:11 359650	INFO [python_manager.cpp->PythonManager::InitializePython:127]	Initializing Python ... 
2023/04/26 09:52:11 378041	INFO [python_manager.cpp->PythonManager::InitializePython:129]	Initializing Python DONE... 
2023/04/26 09:52:11 378049	INFO [python_manager.cpp->PythonManager::InitNumpy:172]	Init numpy... 
2023/04/26 09:52:11 489760	INFO [python_manager.cpp->PythonManager::InitNumpy:174]	Init numpy DONE... 
2023/04/26 09:54:40 635496	INFO [python_manager.cpp->PythonManager::Death:637]	Death()
2023/04/26 09:57:32 814164	WARNING [python_manager.cpp->PythonManager::CheckForErrors:745]	Error, traceback : ['Traceback (most recent call last):
', '  File "C:/Users/user/OneDrive - ESTACA/Documents/GitHub/ESTADRIVE_23/Main_Perception/PythonBridges\\BlocTracking (1).py", line 408, in Core
    ImageOut.data.image_data = drawImage(ImageOut.data.image_data,self.classIds,self.trackingIds,self.trackingBoxes)
', '  File "C:/Users/user/OneDrive - ESTACA/Documents/GitHub/ESTADRIVE_23/Main_Perception/PythonBridges\\BlocTracking (1).py", line 164, in drawImage
    Frame = cv2.rectangle(Frame,(x1,y1),(x2,y2),(244,80,60),2)
', "cv2.error: OpenCV(4.5.4-dev) :-1: error: (-5:Bad argument) in function 'rectangle'
> Overload resolution failed:
>  - Can't parse 'pt1'. Sequence item with index 1 has a wrong type
>  - Can't parse 'pt1'. Sequence item with index 1 has a wrong type
>  - Can't parse 'rec'. Expected sequence length 4, got 2
>  - Can't parse 'rec'. Expected sequence length 4, got 2

"]
2023/04/26 09:57:32 854495	INFO [python_manager.cpp->PythonManager::Death:637]	Death()
2023/04/26 10:04:14 419441	INFO [python_manager.cpp->PythonManager::Death:637]	Death()
2023/04/26 10:05:36 687333	INFO [python_manager.cpp->PythonManager::Death:637]	Death()
2023/04/26 10:09:03 304888	INFO [python_manager.cpp->PythonManager::Death:637]	Death()
