		g3log created log at: Tue Feb 28 10:26:15 2023
		LOG format: [YYYY/MM/DD hh:mm:ss uuu* LEVEL FILE->FUNCTION:LINE] messagen
		(uuu*: microseconds fractions of the seconds value)

2023/02/28 10:26:15 066764	INFO [python_manager.cpp->PythonManager::InitializePython:127]	Initializing Python ... 
2023/02/28 10:26:15 088874	INFO [python_manager.cpp->PythonManager::InitializePython:129]	Initializing Python DONE... 
2023/02/28 10:26:15 088883	INFO [python_manager.cpp->PythonManager::InitNumpy:172]	Init numpy... 
2023/02/28 10:26:15 224863	INFO [python_manager.cpp->PythonManager::InitNumpy:174]	Init numpy DONE... 
2023/02/28 10:26:15 316153	WARNING [python_manager.cpp->PythonManager::CheckForErrors:745]	Error, traceback : ['Traceback (most recent call last):
', '  File "C:/Users/user/OneDrive - ESTACA/Desktop/ESTAPARK2023/RTMapsYOLOv7\\Yolo_RTMaps.py", line 10, in <module>
    from yolov7 import YOLOv7
', '  File "C:/Users/user/OneDrive - ESTACA/Desktop/ESTAPARK2023/RTMapsYOLOv7\\yolov7\\__init__.py", line 1, in <module>
    from .YOLOv7 import YOLOv7
', '  File "C:/Users/user/OneDrive - ESTACA/Desktop/ESTAPARK2023/RTMapsYOLOv7\\yolov7\\YOLOv7.py", line 4, in <module>
    import onnxruntime
', '  File "C:\\Users\\user\\AppData\\Local\\Programs\\Python\\Python38\\lib\\site-packages\\onnxruntime\\__init__.py", line 55, in <module>
    raise import_capi_exception
', '  File "C:\\Users\\user\\AppData\\Local\\Programs\\Python\\Python38\\lib\\site-packages\\onnxruntime\\__init__.py", line 23, in <module>
    from onnxruntime.capi._pybind_state import (
', '  File "C:\\Users\\user\\AppData\\Local\\Programs\\Python\\Python38\\lib\\site-packages\\onnxruntime\\capi\\_pybind_state.py", line 33, in <module>
    from .onnxruntime_pybind11_state import *  # noqa
', 'ImportError: DLL load failed while importing onnxruntime_pybind11_state: The specified module could not be found.
']
