		g3log created log at: Thu Mar 09 15:57:24 2023
		LOG format: [YYYY/MM/DD hh:mm:ss uuu* LEVEL FILE->FUNCTION:LINE] messagen
		(uuu*: microseconds fractions of the seconds value)

2023/03/09 15:57:24 869673	INFO [python_manager.cpp->PythonManager::InitializePython:127]	Initializing Python ... 
2023/03/09 15:57:24 891564	INFO [python_manager.cpp->PythonManager::InitializePython:129]	Initializing Python DONE... 
2023/03/09 15:57:24 891575	INFO [python_manager.cpp->PythonManager::InitNumpy:172]	Init numpy... 
2023/03/09 15:57:25 010733	INFO [python_manager.cpp->PythonManager::InitNumpy:174]	Init numpy DONE... 
2023/03/09 15:57:25 341299	WARNING [python_manager.cpp->PythonManager::CheckForErrors:745]	Error, traceback : ['Traceback (most recent call last):
', '  File "C:/Users/user/OneDrive - ESTACA/Documents/GitHub/ESTADRIVE_23/Main_Perception/PythonBridges\\Yolo_RTMaps2.py", line 173, in Core
    classIdsOut.data = prepareIds(self.CmrObject.class_ids,Ids)
', '  File "C:/Users/user/OneDrive - ESTACA/Documents/GitHub/ESTADRIVE_23/Main_Perception/PythonBridges\\Yolo_RTMaps2.py", line 84, in prepareIds
    nArray = np.append(nArray,array[i])
', 'IndexError: index 1 is out of bounds for axis 0 with size 1
']
2023/03/09 15:57:25 356245	INFO [python_manager.cpp->PythonManager::Death:637]	Death()
2023/03/09 15:58:35 364016	WARNING [python_manager.cpp->PythonManager::CheckForErrors:745]	Error, traceback : ['Traceback (most recent call last):
', '  File "C:/Users/user/OneDrive - ESTACA/Documents/GitHub/ESTADRIVE_23/Main_Perception/PythonBridges\\Yolo_RTMaps2.py", line 173, in Core
    classIdsOut.data = prepareIds(self.CmrObject.class_ids,Ids)
', '  File "C:/Users/user/OneDrive - ESTACA/Documents/GitHub/ESTADRIVE_23/Main_Perception/PythonBridges\\Yolo_RTMaps2.py", line 84, in prepareIds
    nArray = np.append(nArray,array[i])
', 'IndexError: index 1 is out of bounds for axis 0 with size 1
']
2023/03/09 15:58:35 364366	INFO [python_manager.cpp->PythonManager::Death:637]	Death()
2023/03/09 15:58:44 193192	WARNING [python_manager.cpp->PythonManager::CheckForErrors:745]	Error, traceback : ['Traceback (most recent call last):
', '  File "C:/Users/user/OneDrive - ESTACA/Documents/GitHub/ESTADRIVE_23/Main_Perception/PythonBridges\\Yolo_RTMaps2.py", line 173, in Core
    classIdsOut.data = prepareIds(self.CmrObject.class_ids,Ids)
', '  File "C:/Users/user/OneDrive - ESTACA/Documents/GitHub/ESTADRIVE_23/Main_Perception/PythonBridges\\Yolo_RTMaps2.py", line 84, in prepareIds
    nArray = np.append(nArray,array[i])
', 'IndexError: index 1 is out of bounds for axis 0 with size 1
']
2023/03/09 15:58:44 193685	INFO [python_manager.cpp->PythonManager::Death:637]	Death()
2023/03/09 15:59:08 998177	WARNING [python_manager.cpp->PythonManager::CheckForErrors:745]	Error, traceback : ['Traceback (most recent call last):
', '  File "C:/Users/user/OneDrive - ESTACA/Documents/GitHub/ESTADRIVE_23/Main_Perception/PythonBridges\\Yolo_RTMaps2.py", line 173, in Core
    classIdsOut.data = prepareIds(self.CmrObject.class_ids,Ids)
', '  File "C:/Users/user/OneDrive - ESTACA/Documents/GitHub/ESTADRIVE_23/Main_Perception/PythonBridges\\Yolo_RTMaps2.py", line 84, in prepareIds
    nArray = np.append(nArray,array[i])
', 'IndexError: index 1 is out of bounds for axis 0 with size 1
']
2023/03/09 15:59:08 998505	INFO [python_manager.cpp->PythonManager::Death:637]	Death()
2023/03/09 15:59:15 606882	WARNING [python_manager.cpp->PythonManager::CheckForErrors:745]	Error, traceback : ['Traceback (most recent call last):
', '  File "C:/Users/user/OneDrive - ESTACA/Documents/GitHub/ESTADRIVE_23/Main_Perception/PythonBridges\\Yolo_RTMaps2.py", line 173, in Core
    classIdsOut.data = prepareIds(self.CmrObject.class_ids,Ids)
', '  File "C:/Users/user/OneDrive - ESTACA/Documents/GitHub/ESTADRIVE_23/Main_Perception/PythonBridges\\Yolo_RTMaps2.py", line 84, in prepareIds
    nArray = np.append(nArray,array[i])
', 'IndexError: index 2 is out of bounds for axis 0 with size 2
']
2023/03/09 15:59:15 607354	INFO [python_manager.cpp->PythonManager::Death:637]	Death()
2023/03/09 16:00:39 716859	WARNING [python_manager.cpp->PythonManager::CheckForErrors:745]	Error, traceback : ['Traceback (most recent call last):
', '  File "C:/Users/user/OneDrive - ESTACA/Documents/GitHub/ESTADRIVE_23/Main_Perception/PythonBridges\\Yolo_RTMaps2.py", line 173, in Core
    classIdsOut.data = prepareIds(self.CmrObject.class_ids,Ids)
', '  File "C:/Users/user/OneDrive - ESTACA/Documents/GitHub/ESTADRIVE_23/Main_Perception/PythonBridges\\Yolo_RTMaps2.py", line 84, in prepareIds
    nArray = np.append(nArray,array[i])
', 'IndexError: index 2 is out of bounds for axis 0 with size 2
']
2023/03/09 16:00:39 717369	INFO [python_manager.cpp->PythonManager::Death:637]	Death()
2023/03/09 16:03:07 394073	WARNING [python_manager.cpp->PythonManager::CheckForErrors:745]	Error, traceback : ['Traceback (most recent call last):
', '  File "C:/Users/user/OneDrive - ESTACA/Documents/GitHub/ESTADRIVE_23/Main_Perception/PythonBridges\\Yolo_RTMaps2.py", line 177, in Core
    classIdsOut.data = prepareIds(self.CmrObject.class_ids,Ids)
', '  File "C:/Users/user/OneDrive - ESTACA/Documents/GitHub/ESTADRIVE_23/Main_Perception/PythonBridges\\Yolo_RTMaps2.py", line 84, in prepareIds
    nArray = np.append(nArray,array[i])
', 'IndexError: index 3 is out of bounds for axis 0 with size 3
']
2023/03/09 16:03:07 400642	INFO [python_manager.cpp->PythonManager::Death:637]	Death()
2023/03/09 16:04:51 037417	INFO [python_manager.cpp->PythonManager::Death:637]	Death()
2023/03/09 16:06:32 977404	INFO [python_manager.cpp->PythonManager::Death:637]	Death()
2023/03/09 16:07:24 953406	INFO [python_manager.cpp->PythonManager::Death:637]	Death()
2023/03/09 16:08:28 914722	INFO [python_manager.cpp->PythonManager::Death:637]	Death()
2023/03/09 16:09:45 154504	INFO [python_manager.cpp->PythonManager::Death:637]	Death()
2023/03/09 16:10:27 554920	INFO [python_manager.cpp->PythonManager::Death:637]	Death()
2023/03/09 16:11:29 149094	INFO [python_manager.cpp->PythonManager::Death:637]	Death()
2023/03/09 16:22:30 090959	INFO [python_manager.cpp->PythonManager::Death:637]	Death()
2023/03/09 16:36:44 293628	INFO [python_manager.cpp->PythonManager::Death:637]	Death()
2023/03/09 16:37:12 452498	INFO [python_manager.cpp->PythonManager::Death:637]	Death()
2023/03/09 16:39:45 199597	WARNING [python_manager.cpp->PythonManager::CheckForErrors:745]	Error, traceback : ['Traceback (most recent call last):
', '  File "C:/Users/user/OneDrive - ESTACA/Documents/GitHub/ESTADRIVE_23/Main_Perception/PythonBridges\\Yolo_RTMaps2.py", line 138, in Core
    self.CmrObject = filteredIds(self.CmrObject)
', '  File "C:/Users/user/OneDrive - ESTACA/Documents/GitHub/ESTADRIVE_23/Main_Perception/PythonBridges\\Yolo_RTMaps2.py", line 41, in filteredIds
    ind=np.where(input.class_ids > 3)[0]
', "TypeError: '>' not supported between instances of 'list' and 'int'
"]
2023/03/09 16:39:45 219363	INFO [python_manager.cpp->PythonManager::Death:637]	Death()
2023/03/09 16:52:47 721219	INFO [python_manager.cpp->PythonManager::Death:637]	Death()
2023/03/09 16:54:08 480128	INFO [python_manager.cpp->PythonManager::Death:637]	Death()
2023/03/09 16:57:05 028606	INFO [python_manager.cpp->PythonManager::ProcessRTMapsAction:210]	Exiting now! All went well.
